Workbook

Sheet Sheet3
A1: type
A3: Row Labels
A4: Allen Parish Public Safety Complex
A5: Alvarado Parkway Institute
A6: Atlanta U.S. Penitentiary
A7: B.R.R.J. Halifax
A8: Bay County
A9: Bi Incororated, Geo Group Company
A10: Broward Transitional Center
A11: C.B.P. Movement Coordination Area
A12: Calhomi Calhoun County, Battle Cr,Mi
A13: California Men Colony, West
... A50: Grand Total

Sheet Sheet1
J1: =SUM(J3:J651)/SUM(H3:H651) -> 0.90337409
A2: detention_facility_first | B2: cleaned_facility_name | C2: facility_code | D2: state | E2: city | F2: COUNTY | G2: type | H2: count | I2: covered? | J2: covered?
A3: ADAMS COUNTY CORRECTIONAL CENTER | B3: Alexandria Staging Facility | C3: JENATLA | D3: LA | E3: Alexandria | G3: {=_xlfn.IFS( ISNUMBER(SEARCH("hold",C3)),"hold", ISNUMBER(SEARCH("youth",C3)),"youth", ISNUMBER(SEARCH("juve",C3)),"youth", OR(ISNUMBER(SEARCH("health",B3)),ISNUMBER(SEARCH("care ",B3)),ISNUMBER(SEARCH("psych",B3)),ISNUMBER(SEARCH("medical",B3)),ISNUMBER(SEARCH("hospital",B3))),"medical", ISNUMBER(SEARCH("correct",B3)),"correctional", ISNUMBER(SEARCH("process",B3)),"processing", ISNUMBER(SEARCH("detention center",B3)),"detention", ISNUMBER(SEARCH("detention fac",B3)),"detention", ISNUMBER(SEARCH("staging",B3)),"staging", ISNUMBER(SEARCH("prison",B3)),"prison", ISNUMBER(SEARCH("penet",B3)),"prison", ISNUMBER(SEARCH("jail",B3)),"jail", ISNUMBER(SEARCH("detention",B3)),"detention", ISNUMBER(SEARCH("sheriff",B3)),"sheriff/police", ISNUMBER(SEARCH("police",B3)),"sheriff/police", TRUE,"" )} -> staging | H3: =INDEX(Sheet2!B:B,MATCH(C3,Sheet2!A:A,0),1) -> 84941 | I3: =3-COUNTBLANK(D3:F3) -> 2 | J3: =IF(I3>=2,H3,0) -> 84941
A4: ADELANTO ICE PROCESSING CENTER | B4: Port Isabel Service Processing Center | C4: PIC | D4: TX | E4: Los Fresnos | G4: {=_xlfn.IFS( ISNUMBER(SEARCH("hold",C4)),"hold", ISNUMBER(SEARCH("youth",C4)),"youth", ISNUMBER(SEARCH("juve",C4)),"youth", OR(ISNUMBER(SEARCH("health",B4)),ISNUMBER(SEARCH("care ",B4)),ISNUMBER(SEARCH("psych",B4)),ISNUMBER(SEARCH("medical",B4)),ISNUMBER(SEARCH("hospital",B4))),"medical", ISNUMBER(SEARCH("correct",B4)),"correctional", ISNUMBER(SEARCH("process",B4)),"processing", ISNUMBER(SEARCH("detention center",B4)),"detention", ISNUMBER(SEARCH("detention fac",B4)),"detention", ISNUMBER(SEARCH("staging",B4)),"staging", ISNUMBER(SEARCH("prison",B4)),"prison", ISNUMBER(SEARCH("penet",B4)),"prison", ISNUMBER(SEARCH("jail",B4)),"jail", ISNUMBER(SEARCH("detention",B4)),"detention", ISNUMBER(SEARCH("sheriff",B4)),"sheriff/police", ISNUMBER(SEARCH("police",B4)),"sheriff/police", TRUE,"" )} -> processing | H4: =INDEX(Sheet2!B:B,MATCH(C4,Sheet2!A:A,0),1) -> 66973 | I4: =3-COUNTBLANK(D4:F4) -> 2 | J4: =IF(I4>=2,H4,0) -> 66973
A5: AGUADILLA SPC | B5: Florence Staging Facility | C5: FSF | D5: AZ | E5: Florence | G5: {=_xlfn.IFS( ISNUMBER(SEARCH("hold",C5)),"hold", ISNUMBER(SEARCH("youth",C5)),"youth", ISNUMBER(SEARCH("juve",C5)),"youth", OR(ISNUMBER(SEARCH("health",B5)),ISNUMBER(SEARCH("care ",B5)),ISNUMBER(SEARCH("psych",B5)),ISNUMBER(SEARCH("medical",B5)),ISNUMBER(SEARCH("hospital",B5))),"medical", ISNUMBER(SEARCH("correct",B5)),"correctional", ISNUMBER(SEARCH("process",B5)),"processing", ISNUMBER(SEARCH("detention center",B5)),"detention", ISNUMBER(SEARCH("detention fac",B5)),"detention", ISNUMBER(SEARCH("staging",B5)),"staging", ISNUMBER(SEARCH("prison",B5)),"prison", ISNUMBER(SEARCH("penet",B5)),"prison", ISNUMBER(SEARCH("jail",B5)),"jail", ISNUMBER(SEARCH("detention",B5)),"detention", ISNUMBER(SEARCH("sheriff",B5)),"sheriff/police", ISNUMBER(SEARCH("police",B5)),"sheriff/police", TRUE,"" )} -> staging | H5: =INDEX(Sheet2!B:B,MATCH(C5,Sheet2!A:A,0),1) -> 65977 | I5: =3-COUNTBLANK(D5:F5) -> 2 | J5: =IF(I5>=2,H5,0) -> 65977
A6: ALAMANCE CO. DET. FACILITY | B6: Pine Prairie I.C.E. Processing Center | C6: PINEPLA | D6: LA | E6: Pine Prairie | G6: {=_xlfn.IFS( ISNUMBER(SEARCH("hold",C6)),"hold", ISNUMBER(SEARCH("youth",C6)),"youth", ISNUMBER(SEARCH("juve",C6)),"youth", OR(ISNUMBER(SEARCH("health",B6)),ISNUMBER(SEARCH("care ",B6)),ISNUMBER(SEARCH("psych",B6)),ISNUMBER(SEARCH("medical",B6)),ISNUMBER(SEARCH("hospital",B6))),"medical", ISNUMBER(SEARCH("correct",B6)),"correctional", ISNUMBER(SEARCH("process",B6)),"processing", ISNUMBER(SEARCH("detention center",B6)),"detention", ISNUMBER(SEARCH("detention fac",B6)),"detention", ISNUMBER(SEARCH("staging",B6)),"staging", ISNUMBER(SEARCH("prison",B6)),"prison", ISNUMBER(SEARCH("penet",B6)),"prison", ISNUMBER(SEARCH("jail",B6)),"jail", ISNUMBER(SEARCH("detention",B6)),"detention", ISNUMBER(SEARCH("sheriff",B6)),"sheriff/police", ISNUMBER(SEARCH("police",B6)),"sheriff/police", TRUE,"" )} -> processing | H6: =INDEX(Sheet2!B:B,MATCH(C6,Sheet2!A:A,0),1) -> 35285 | I6: =3-COUNTBLANK(D6:F6) -> 2 | J6: =IF(I6>=2,H6,0) -> 35285
A7: ALAMO POLICE DEPT. | B7: Montgomery Processing Center | C7: MTGPCTX | D7: TX | E7: Conroe | F7: Montgomery | G7: {=_xlfn.IFS( ISNUMBER(SEARCH("hold",C7)),"hold", ISNUMBER(SEARCH("youth",C7)),"youth", ISNUMBER(SEARCH("juve",C7)),"youth", OR(ISNUMBER(SEARCH("health",B7)),ISNUMBER(SEARCH("care ",B7)),ISNUMBER(SEARCH("psych",B7)),ISNUMBER(SEARCH("medical",B7)),ISNUMBER(SEARCH("hospital",B7))),"medical", ISNUMBER(SEARCH("correct",B7)),"correctional", ISNUMBER(SEARCH("process",B7)),"processing", ISNUMBER(SEARCH("detention center",B7)),"detention", ISNUMBER(SEARCH("detention fac",B7)),"detention", ISNUMBER(SEARCH("staging",B7)),"staging", ISNUMBER(SEARCH("prison",B7)),"prison", ISNUMBER(SEARCH("penet",B7)),"prison", ISNUMBER(SEARCH("jail",B7)),"jail", ISNUMBER(SEARCH("detention",B7)),"detention", ISNUMBER(SEARCH("sheriff",B7)),"sheriff/police", ISNUMBER(SEARCH("police",B7)),"sheriff/police", TRUE,"" )} -> processing | H7: =INDEX(Sheet2!B:B,MATCH(C7,Sheet2!A:A,0),1) -> 32270 | I7: =3-COUNTBLANK(D7:F7) -> 3 | J7: =IF(I7>=2,H7,0) -> 32270
A8: ALAMOSA HOLDROOM | B8: Eloy Fed Center Facility (Corrections Corporation of America) | C8: EAZ | D8: AZ | E8: Eloy | G8: {=_xlfn.IFS( ISNUMBER(SEARCH("hold",C8)),"hold", ISNUMBER(SEARCH("youth",C8)),"youth", ISNUMBER(SEARCH("juve",C8)),"youth", OR(ISNUMBER(SEARCH("health",B8)),ISNUMBER(SEARCH("care ",B8)),ISNUMBER(SEARCH("psych",B8)),ISNUMBER(SEARCH("medical",B8)),ISNUMBER(SEARCH("hospital",B8))),"medical", ISNUMBER(SEARCH("correct",B8)),"correctional", ISNUMBER(SEARCH("process",B8)),"processing", ISNUMBER(SEARCH("detention center",B8)),"detention", ISNUMBER(SEARCH("detention fac",B8)),"detention", ISNUMBER(SEARCH("staging",B8)),"staging", ISNUMBER(SEARCH("prison",B8)),"prison", ISNUMBER(SEARCH("penet",B8)),"prison", ISNUMBER(SEARCH("jail",B8)),"jail", ISNUMBER(SEARCH("detention",B8)),"detention", ISNUMBER(SEARCH("sheriff",B8)),"sheriff/police", ISNUMBER(SEARCH("police",B8)),"sheriff/police", TRUE,"" )} -> correctional | H8: =INDEX(Sheet2!B:B,MATCH(C8,Sheet2!A:A,0),1) -> 28159 | I8: =3-COUNTBLANK(D8:F8) -> 2 | J8: =IF(I8>=2,H8,0) -> 28159
A9: ALBANY HOLDROOM | B9: Otay Mesa Detention Center | C9: CCASDCA | D9: CA | E9: San Diego | G9: {=_xlfn.IFS( ISNUMBER(SEARCH("hold",C9)),"hold", ISNUMBER(SEARCH("youth",C9)),"youth", ISNUMBER(SEARCH("juve",C9)),"youth", OR(ISNUMBER(SEARCH("health",B9)),ISNUMBER(SEARCH("care ",B9)),ISNUMBER(SEARCH("psych",B9)),ISNUMBER(SEARCH("medical",B9)),ISNUMBER(SEARCH("hospital",B9))),"medical", ISNUMBER(SEARCH("correct",B9)),"correctional", ISNUMBER(SEARCH("process",B9)),"processing", ISNUMBER(SEARCH("detention center",B9)),"detention", ISNUMBER(SEARCH("detention fac",B9)),"detention", ISNUMBER(SEARCH("staging",B9)),"staging", ISNUMBER(SEARCH("prison",B9)),"prison", ISNUMBER(SEARCH("penet",B9)),"prison", ISNUMBER(SEARCH("jail",B9)),"jail", ISNUMBER(SEARCH("detention",B9)),"detention", ISNUMBER(SEARCH("sheriff",B9)),"sheriff/police", ISNUMBER(SEARCH("police",B9)),"sheriff/police", TRUE,"" )} -> detention | H9: =INDEX(Sheet2!B:B,MATCH(C9,Sheet2!A:A,0),1) -> 27619 | I9: =3-COUNTBLANK(D9:F9) -> 2 | J9: =IF(I9>=2,H9,0) -> 27619
A10: ALBUQUERQUE HOLD ROOM | B10: South Texas I.C.E. Processing Center | C10: STCDFTX | D10: TX | E10: Pearsall | G10: {=_xlfn.IFS( ISNUMBER(SEARCH("hold",C10)),"hold", ISNUMBER(SEARCH("youth",C10)),"youth", ISNUMBER(SEARCH("juve",C10)),"youth", OR(ISNUMBER(SEARCH("health",B10)),ISNUMBER(SEARCH("care ",B10)),ISNUMBER(SEARCH("psych",B10)),ISNUMBER(SEARCH("medical",B10)),ISNUMBER(SEARCH("hospital",B10))),"medical", ISNUMBER(SEARCH("correct",B10)),"correctional", ISNUMBER(SEARCH("process",B10)),"processing", ISNUMBER(SEARCH("detention center",B10)),"detention", ISNUMBER(SEARCH("detention fac",B10)),"detention", ISNUMBER(SEARCH("staging",B10)),"staging", ISNUMBER(SEARCH("prison",B10)),"prison", ISNUMBER(SEARCH("penet",B10)),"prison", ISNUMBER(SEARCH("jail",B10)),"jail", ISNUMBER(SEARCH("detention",B10)),"detention", ISNUMBER(SEARCH("sheriff",B10)),"sheriff/police", ISNUMBER(SEARCH("police",B10)),"sheriff/police", TRUE,"" )} -> processing | H10: =INDEX(Sheet2!B:B,MATCH(C10,Sheet2!A:A,0),1) -> 27318 | I10: =3-COUNTBLANK(D10:F10) -> 2 | J10: =IF(I10>=2,H10,0) -> 27318
A11: ALEXANDRIA CITY JAIL | B11: Stewart Detention Center | C11: STWRTGA | D11: GA | E11: Lumpkin | G11: {=_xlfn.IFS( ISNUMBER(SEARCH("hold",C11)),"hold", ISNUMBER(SEARCH("youth",C11)),"youth", ISNUMBER(SEARCH("juve",C11)),"youth", OR(ISNUMBER(SEARCH("health",B11)),ISNUMBER(SEARCH("care ",B11)),ISNUMBER(SEARCH("psych",B11)),ISNUMBER(SEARCH("medical",B11)),ISNUMBER(SEARCH("hospital",B11))),"medical", ISNUMBER(SEARCH("correct",B11)),"correctional", ISNUMBER(SEARCH("process",B11)),"processing", ISNUMBER(SEARCH("detention center",B11)),"detention", ISNUMBER(SEARCH("detention fac",B11)),"detention", ISNUMBER(SEARCH("staging",B11)),"staging", ISNUMBER(SEARCH("prison",B11)),"prison", ISNUMBER(SEARCH("penet",B11)),"prison", ISNUMBER(SEARCH("jail",B11)),"jail", ISNUMBER(SEARCH("detention",B11)),"detention", ISNUMBER(SEARCH("sheriff",B11)),"sheriff/police", ISNUMBER(SEARCH("police",B11)),"sheriff/police", TRUE,"" )} -> detention | H11: =INDEX(Sheet2!B:B,MATCH(C11,Sheet2!A:A,0),1) -> 26209 | I11: =3-COUNTBLANK(D11:F11) -> 2 | J11: =IF(I11>=2,H11,0) -> 26209
A12: ALEXANDRIA STAGING FACILITY | B12: Winn Correctional Center | C12: LAWINCI | D12: LA | E12: Winnfield | G12: {=_xlfn.IFS( ISNUMBER(SEARCH("hold",C12)),"hold", ISNUMBER(SEARCH("youth",C12)),"youth", ISNUMBER(SEARCH("juve",C12)),"youth", OR(ISNUMBER(SEARCH("health",B12)),ISNUMBER(SEARCH("care ",B12)),ISNUMBER(SEARCH("psych",B12)),ISNUMBER(SEARCH("medical",B12)),ISNUMBER(SEARCH("hospital",B12))),"medical", ISNUMBER(SEARCH("correct",B12)),"correctional", ISNUMBER(SEARCH("process",B12)),"processing", ISNUMBER(SEARCH("detention center",B12)),"detention", ISNUMBER(SEARCH("detention fac",B12)),"detention", ISNUMBER(SEARCH("staging",B12)),"staging", ISNUMBER(SEARCH("prison",B12)),"prison", ISNUMBER(SEARCH("penet",B12)),"prison", ISNUMBER(SEARCH("jail",B12)),"jail", ISNUMBER(SEARCH("detention",B12)),"detention", ISNUMBER(SEARCH("sheriff",B12)),"sheriff/police", ISNUMBER(SEARCH("police",B12)),"sheriff/police", TRUE,"" )} -> correctional | H12: =INDEX(Sheet2!B:B,MATCH(C12,Sheet2!A:A,0),1) -> 25935 | I12: =3-COUNTBLANK(D12:F12) -> 2 | J12: =IF(I12>=2,H12,0) -> 25935
A13: ALLEGANY COUNTY JAIL | B13: Florence Service Processing Center | C13: FLO | D13: AZ | E13: Florence | G13: {=_xlfn.IFS( ISNUMBER(SEARCH("hold",C13)),"hold", ISNUMBER(SEARCH("youth",C13)),"youth", ISNUMBER(SEARCH("juve",C13)),"youth", OR(ISNUMBER(SEARCH("health",B13)),ISNUMBER(SEARCH("care ",B13)),ISNUMBER(SEARCH("psych",B13)),ISNUMBER(SEARCH("medical",B13)),ISNUMBER(SEARCH("hospital",B13))),"medical", ISNUMBER(SEARCH("correct",B13)),"correctional", ISNUMBER(SEARCH("process",B13)),"processing", ISNUMBER(SEARCH("detention center",B13)),"detention", ISNUMBER(SEARCH("detention fac",B13)),"detention", ISNUMBER(SEARCH("staging",B13)),"staging", ISNUMBER(SEARCH("prison",B13)),"prison", ISNUMBER(SEARCH("penet",B13)),"prison", ISNUMBER(SEARCH("jail",B13)),"jail", ISNUMBER(SEARCH("detention",B13)),"detention", ISNUMBER(SEARCH("sheriff",B13)),"sheriff/police", ISNUMBER(SEARCH("police",B13)),"sheriff/police", TRUE,"" )} -> processing | H13: =INDEX(Sheet2!B:B,MATCH(C13,Sheet2!A:A,0),1) -> 25888 | I13: =3-COUNTBLANK(D13:F13) -> 2 | J13: =IF(I13>=2,H13,0) -> 25888
A14: ALLEN PARISH PUBLIC SAFETY COMPLEX | B14: Adams County Correctional Center | C14: ADAMSMS | D14: MS | E14: Natchez | F14: Adams | G14: {=_xlfn.IFS( ISNUMBER(SEARCH("hold",C14)),"hold", ISNUMBER(SEARCH("youth",C14)),"youth", ISNUMBER(SEARCH("juve",C14)),"youth", OR(ISNUMBER(SEARCH("health",B14)),ISNUMBER(SEARCH("care ",B14)),ISNUMBER(SEARCH("psych",B14)),ISNUMBER(SEARCH("medical",B14)),ISNUMBER(SEARCH("hospital",B14))),"medical", ISNUMBER(SEARCH("correct",B14)),"correctional", ISNUMBER(SEARCH("process",B14)),"processing", ISNUMBER(SEARCH("detention center",B14)),"detention", ISNUMBER(SEARCH("detention fac",B14)),"detention", ISNUMBER(SEARCH("staging",B14)),"staging", ISNUMBER(SEARCH("prison",B14)),"prison", ISNUMBER(SEARCH("penet",B14)),"prison", ISNUMBER(SEARCH("jail",B14)),"jail", ISNUMBER(SEARCH("detention",B14)),"detention", ISNUMBER(SEARCH("sheriff",B14)),"sheriff/police", ISNUMBER(SEARCH("police",B14)),"sheriff/police", TRUE,"" )} -> correctional | H14: =INDEX(Sheet2!B:B,MATCH(C14,Sheet2!A:A,0),1) -> 25721 | I14: =3-COUNTBLANK(D14:F14) -> 3 | J14: =IF(I14>=2,H14,0) -> 25721
A15: ALVARADO PARKWAY INSTITUTE | B15: Prairieland Detention Center | C15: PRLDCTX | D15: TX | E15: Alvarado | G15: {=_xlfn.IFS( ISNUMBER(SEARCH("hold",C15)),"hold", ISNUMBER(SEARCH("youth",C15)),"youth", ISNUMBER(SEARCH("juve",C15)),"youth", OR(ISNUMBER(SEARCH("health",B15)),ISNUMBER(SEARCH("care ",B15)),ISNUMBER(SEARCH("psych",B15)),ISNUMBER(SEARCH("medical",B15)),ISNUMBER(SEARCH("hospital",B15))),"medical", ISNUMBER(SEARCH("correct",B15)),"correctional", ISNUMBER(SEARCH("process",B15)),"processing", ISNUMBER(SEARCH("detention center",B15)),"detention", ISNUMBER(SEARCH("detention fac",B15)),"detention", ISNUMBER(SEARCH("staging",B15)),"staging", ISNUMBER(SEARCH("prison",B15)),"prison", ISNUMBER(SEARCH("penet",B15)),"prison", ISNUMBER(SEARCH("jail",B15)),"jail", ISNUMBER(SEARCH("detention",B15)),"detention", ISNUMBER(SEARCH("sheriff",B15)),"sheriff/police", ISNUMBER(SEARCH("police",B15)),"sheriff/police", TRUE,"" )} -> detention | H15: =INDEX(Sheet2!B:B,MATCH(C15,Sheet2!A:A,0),1) -> 25666 | I15: =3-COUNTBLANK(D15:F15) -> 2 | J15: =IF(I15>=2,H15,0) -> 25666
A16: AMARILLO HOLD ROOM | B16: Krome North Service Processing Center | C16: KRO | D16: FL | E16: Miami | G16: {=_xlfn.IFS( ISNUMBER(SEARCH("hold",C16)),"hold", ISNUMBER(SEARCH("youth",C16)),"youth", ISNUMBER(SEARCH("juve",C16)),"youth", OR(ISNUMBER(SEARCH("health",B16)),ISNUMBER(SEARCH("care ",B16)),ISNUMBER(SEARCH("psych",B16)),ISNUMBER(SEARCH("medical",B16)),ISNUMBER(SEARCH("hospital",B16))),"medical", ISNUMBER(SEARCH("correct",B16)),"correctional", ISNUMBER(SEARCH("process",B16)),"processing", ISNUMBER(SEARCH("detention center",B16)),"detention", ISNUMBER(SEARCH("detention fac",B16)),"detention", ISNUMBER(SEARCH("staging",B16)),"staging", ISNUMBER(SEARCH("prison",B16)),"prison", ISNUMBER(SEARCH("penet",B16)),"prison", ISNUMBER(SEARCH("jail",B16)),"jail", ISNUMBER(SEARCH("detention",B16)),"detention", ISNUMBER(SEARCH("sheriff",B16)),"sheriff/police", ISNUMBER(SEARCH("police",B16)),"sheriff/police", TRUE,"" )} -> processing | H16: =INDEX(Sheet2!B:B,MATCH(C16,Sheet2!A:A,0),1) -> 25522 | I16: =3-COUNTBLANK(D16:F16) -> 2 | J16: =IF(I16>=2,H16,0) -> 25522
A17: ANCHORAGE JAIL | B17: El Paso Service Processing Center | C17: EPC | D17: TX | E17: El Paso | G17: {=_xlfn.IFS( ISNUMBER(SEARCH("hold",C17)),"hold", ISNUMBER(SEARCH("youth",C17)),"youth", ISNUMBER(SEARCH("juve",C17)),"youth", OR(ISNUMBER(SEARCH("health",B17)),ISNUMBER(SEARCH("care ",B17)),ISNUMBER(SEARCH("psych",B17)),ISNUMBER(SEARCH("medical",B17)),ISNUMBER(SEARCH("hospital",B17))),"medical", ISNUMBER(SEARCH("correct",B17)),"correctional", ISNUMBER(SEARCH("process",B17)),"processing", ISNUMBER(SEARCH("detention center",B17)),"detention", ISNUMBER(SEARCH("detention fac",B17)),"detention", ISNUMBER(SEARCH("staging",B17)),"staging", ISNUMBER(SEARCH("prison",B17)),"prison", ISNUMBER(SEARCH("penet",B17)),"prison", ISNUMBER(SEARCH("jail",B17)),"jail", ISNUMBER(SEARCH("detention",B17)),"detention", ISNUMBER(SEARCH("sheriff",B17)),"sheriff/police", ISNUMBER(SEARCH("police",B17)),"sheriff/police", TRUE,"" )} -> processing | H17: =INDEX(Sheet2!B:B,MATCH(C17,Sheet2!A:A,0),1) -> 22591 | I17: =3-COUNTBLANK(D17:F17) -> 2 | J17: =IF(I17>=2,H17,0) -> 22591
A18: ANCHORAGE SUB-OFFICE HOLD ROOM | B18: Karnes County Immigration Process Center | C18: KRNRCTX | D18: TX | F18: Karnes | G18: {=_xlfn.IFS( ISNUMBER(SEARCH("hold",C18)),"hold", ISNUMBER(SEARCH("youth",C18)),"youth", ISNUMBER(SEARCH("juve",C18)),"youth", OR(ISNUMBER(SEARCH("health",B18)),ISNUMBER(SEARCH("care ",B18)),ISNUMBER(SEARCH("psych",B18)),ISNUMBER(SEARCH("medical",B18)),ISNUMBER(SEARCH("hospital",B18))),"medical", ISNUMBER(SEARCH("correct",B18)),"correctional", ISNUMBER(SEARCH("process",B18)),"processing", ISNUMBER(SEARCH("detention center",B18)),"detention", ISNUMBER(SEARCH("detention fac",B18)),"detention", ISNUMBER(SEARCH("staging",B18)),"staging", ISNUMBER(SEARCH("prison",B18)),"prison", ISNUMBER(SEARCH("penet",B18)),"prison", ISNUMBER(SEARCH("jail",B18)),"jail", ISNUMBER(SEARCH("detention",B18)),"detention", ISNUMBER(SEARCH("sheriff",B18)),"sheriff/police", ISNUMBER(SEARCH("police",B18)),"sheriff/police", TRUE,"" )} -> processing | H18: =INDEX(Sheet2!B:B,MATCH(C18,Sheet2!A:A,0),1) -> 21935 | I18: =3-COUNTBLANK(D18:F18) -> 2 | J18: =IF(I18>=2,H18,0) -> 21935
A19: ANDERSON COUNTY DET CENTER | B19: Dallas F.O. Hold | C19: DALHOLD | D19: TX | E19: Dallas | G19: {=_xlfn.IFS( ISNUMBER(SEARCH("hold",C19)),"hold", ISNUMBER(SEARCH("youth",C19)),"youth", ISNUMBER(SEARCH("juve",C19)),"youth", OR(ISNUMBER(SEARCH("health",B19)),ISNUMBER(SEARCH("care ",B19)),ISNUMBER(SEARCH("psych",B19)),ISNUMBER(SEARCH("medical",B19)),ISNUMBER(SEARCH("hospital",B19))),"medical", ISNUMBER(SEARCH("correct",B19)),"correctional", ISNUMBER(SEARCH("process",B19)),"processing", ISNUMBER(SEARCH("detention center",B19)),"detention", ISNUMBER(SEARCH("detention fac",B19)),"detention", ISNUMBER(SEARCH("staging",B19)),"staging", ISNUMBER(SEARCH("prison",B19)),"prison", ISNUMBER(SEARCH("penet",B19)),"prison", ISNUMBER(SEARCH("jail",B19)),"jail", ISNUMBER(SEARCH("detention",B19)),"detention", ISNUMBER(SEARCH("sheriff",B19)),"sheriff/police", ISNUMBER(SEARCH("police",B19)),"sheriff/police", TRUE,"" )} -> hold | H19: =INDEX(Sheet2!B:B,MATCH(C19,Sheet2!A:A,0),1) -> 21680 | I19: =3-COUNTBLANK(D19:F19) -> 2 | J19: =IF(I19>=2,H19,0) -> 21680
A20: ARAPAHOE COUNTY JAIL | B20: Otero County Processing Center | C20: OTRPCNM | D20: NM | F20: Otero | G20: {=_xlfn.IFS( ISNUMBER(SEARCH("hold",C20)),"hold", ISNUMBER(SEARCH("youth",C20)),"youth", ISNUMBER(SEARCH("juve",C20)),"youth", OR(ISNUMBER(SEARCH("health",B20)),ISNUMBER(SEARCH("care ",B20)),ISNUMBER(SEARCH("psych",B20)),ISNUMBER(SEARCH("medical",B20)),ISNUMBER(SEARCH("hospital",B20))),"medical", ISNUMBER(SEARCH("correct",B20)),"correctional", ISNUMBER(SEARCH("process",B20)),"processing", ISNUMBER(SEARCH("detention center",B20)),"detention", ISNUMBER(SEARCH("detention fac",B20)),"detention", ISNUMBER(SEARCH("staging",B20)),"staging", ISNUMBER(SEARCH("prison",B20)),"prison", ISNUMBER(SEARCH("penet",B20)),"prison", ISNUMBER(SEARCH("jail",B20)),"jail", ISNUMBER(SEARCH("detention",B20)),"detention", ISNUMBER(SEARCH("sheriff",B20)),"sheriff/police", ISNUMBER(SEARCH("police",B20)),"sheriff/police", TRUE,"" )} -> processing | H20: =INDEX(Sheet2!B:B,MATCH(C20,Sheet2!A:A,0),1) -> 21573 | I20: =3-COUNTBLANK(D20:F20) -> 2 | J20: =IF(I20>=2,H20,0) -> 21573
A21: ARIZONA STATE PRISON - YUMA | B21: Central Louisiana I.C.E. Processing Center | C21: JENADLA | D21: LA | E21: Pine Prairie | G21: {=_xlfn.IFS( ISNUMBER(SEARCH("hold",C21)),"hold", ISNUMBER(SEARCH("youth",C21)),"youth", ISNUMBER(SEARCH("juve",C21)),"youth", OR(ISNUMBER(SEARCH("health",B21)),ISNUMBER(SEARCH("care ",B21)),ISNUMBER(SEARCH("psych",B21)),ISNUMBER(SEARCH("medical",B21)),ISNUMBER(SEARCH("hospital",B21))),"medical", ISNUMBER(SEARCH("correct",B21)),"correctional", ISNUMBER(SEARCH("process",B21)),"processing", ISNUMBER(SEARCH("detention center",B21)),"detention", ISNUMBER(SEARCH("detention fac",B21)),"detention", ISNUMBER(SEARCH("staging",B21)),"staging", ISNUMBER(SEARCH("prison",B21)),"prison", ISNUMBER(SEARCH("penet",B21)),"prison", ISNUMBER(SEARCH("jail",B21)),"jail", ISNUMBER(SEARCH("detention",B21)),"detention", ISNUMBER(SEARCH("sheriff",B21)),"sheriff/police", ISNUMBER(SEARCH("police",B21)),"sheriff/police", TRUE,"" )} -> processing | H21: =INDEX(Sheet2!B:B,MATCH(C21,Sheet2!A:A,0),1) -> 21503 | I21: =3-COUNTBLANK(D21:F21) -> 2 | J21: =IF(I21>=2,H21,0) -> 21503
A22: ATHENS, TX HOLD ROOM | B22: Jackson Parish Correctional Center | C22: JKPCCLA | D22: LA | F22: Jackson | G22: {=_xlfn.IFS( ISNUMBER(SEARCH("hold",C22)),"hold", ISNUMBER(SEARCH("youth",C22)),"youth", ISNUMBER(SEARCH("juve",C22)),"youth", OR(ISNUMBER(SEARCH("health",B22)),ISNUMBER(SEARCH("care ",B22)),ISNUMBER(SEARCH("psych",B22)),ISNUMBER(SEARCH("medical",B22)),ISNUMBER(SEARCH("hospital",B22))),"medical", ISNUMBER(SEARCH("correct",B22)),"correctional", ISNUMBER(SEARCH("process",B22)),"processing", ISNUMBER(SEARCH("detention center",B22)),"detention", ISNUMBER(SEARCH("detention fac",B22)),"detention", ISNUMBER(SEARCH("staging",B22)),"staging", ISNUMBER(SEARCH("prison",B22)),"prison", ISNUMBER(SEARCH("penet",B22)),"prison", ISNUMBER(SEARCH("jail",B22)),"jail", ISNUMBER(SEARCH("detention",B22)),"detention", ISNUMBER(SEARCH("sheriff",B22)),"sheriff/police", ISNUMBER(SEARCH("police",B22)),"sheriff/police", TRUE,"" )} -> correctional | H22: =INDEX(Sheet2!B:B,MATCH(C22,Sheet2!A:A,0),1) -> 21503 | I22: =3-COUNTBLANK(D22:F22) -> 2 | J22: =IF(I22>=2,H22,0) -> 21503
A23: ATLANTA DIST. HOLD RM | B23: Montgomery Hold Room | C23: MTGHOLD | D23: TX | E23: Conroe | F23: Montgomery | G23: {=_xlfn.IFS( ISNUMBER(SEARCH("hold",C23)),"hold", ISNUMBER(SEARCH("youth",C23)),"youth", ISNUMBER(SEARCH("juve",C23)),"youth", OR(ISNUMBER(SEARCH("health",B23)),ISNUMBER(SEARCH("care ",B23)),ISNUMBER(SEARCH("psych",B23)),ISNUMBER(SEARCH("medical",B23)),ISNUMBER(SEARCH("hospital",B23))),"medical", ISNUMBER(SEARCH("correct",B23)),"correctional", ISNUMBER(SEARCH("process",B23)),"processing", ISNUMBER(SEARCH("detention center",B23)),"detention", ISNUMBER(SEARCH("detention fac",B23)),"detention", ISNUMBER(SEARCH("staging",B23)),"staging", ISNUMBER(SEARCH("prison",B23)),"prison", ISNUMBER(SEARCH("penet",B23)),"prison", ISNUMBER(SEARCH("jail",B23)),"jail", ISNUMBER(SEARCH("detention",B23)),"detention", ISNUMBER(SEARCH("sheriff",B23)),"sheriff/police", ISNUMBER(SEARCH("police",B23)),"sheriff/police", TRUE,"" )} -> hold | H23: =INDEX(Sheet2!B:B,MATCH(C23,Sheet2!A:A,0),1) -> 21420 | I23: =3-COUNTBLANK(D23:F23) -> 3 | J23: =IF(I23>=2,H23,0) -> 21420
A24: ATLANTA PRETRIAL DETN CTR | B24: El Valle Detention Facility | C24: ELVDFTX | D24: TX | E24: Raymondville | G24: {=_xlfn.IFS( ISNUMBER(SEARCH("hold",C24)),"hold", ISNUMBER(SEARCH("youth",C24)),"youth", ISNUMBER(SEARCH("juve",C24)),"youth", OR(ISNUMBER(SEARCH("health",B24)),ISNUMBER(SEARCH("care ",B24)),ISNUMBER(SEARCH("psych",B24)),ISNUMBER(SEARCH("medical",B24)),ISNUMBER(SEARCH("hospital",B24))),"medical", ISNUMBER(SEARCH("correct",B24)),"correctional", ISNUMBER(SEARCH("process",B24)),"processing", ISNUMBER(SEARCH("detention center",B24)),"detention", ISNUMBER(SEARCH("detention fac",B24)),"detention", ISNUMBER(SEARCH("staging",B24)),"staging", ISNUMBER(SEARCH("prison",B24)),"prison", ISNUMBER(SEARCH("penet",B24)),"prison", ISNUMBER(SEARCH("jail",B24)),"jail", ISNUMBER(SEARCH("detention",B24)),"detention", ISNUMBER(SEARCH("sheriff",B24)),"sheriff/police", ISNUMBER(SEARCH("police",B24)),"sheriff/police", TRUE,"" )} -> detention | H24: =INDEX(Sheet2!B:B,MATCH(C24,Sheet2!A:A,0),1) -> 20063 | I24: =3-COUNTBLANK(D24:F24) -> 2 | J24: =IF(I24>=2,H24,0) -> 20063
A25: ATLANTA U.S. PEN. | B25: Bluebonnet Detention Facility | C25: BLBNATX | D25: TX | E25: Anson | G25: {=_xlfn.IFS( ISNUMBER(SEARCH("hold",C25)),"hold", ISNUMBER(SEARCH("youth",C25)),"youth", ISNUMBER(SEARCH("juve",C25)),"youth", OR(ISNUMBER(SEARCH("health",B25)),ISNUMBER(SEARCH("care ",B25)),ISNUMBER(SEARCH("psych",B25)),ISNUMBER(SEARCH("medical",B25)),ISNUMBER(SEARCH("hospital",B25))),"medical", ISNUMBER(SEARCH("correct",B25)),"correctional", ISNUMBER(SEARCH("process",B25)),"processing", ISNUMBER(SEARCH("detention center",B25)),"detention", ISNUMBER(SEARCH("detention fac",B25)),"detention", ISNUMBER(SEARCH("staging",B25)),"staging", ISNUMBER(SEARCH("prison",B25)),"prison", ISNUMBER(SEARCH("penet",B25)),"prison", ISNUMBER(SEARCH("jail",B25)),"jail", ISNUMBER(SEARCH("detention",B25)),"detention", ISNUMBER(SEARCH("sheriff",B25)),"sheriff/police", ISNUMBER(SEARCH("police",B25)),"sheriff/police", TRUE,"" )} -> detention | H25: =INDEX(Sheet2!B:B,MATCH(C25,Sheet2!A:A,0),1) -> 18893 | I25: =3-COUNTBLANK(D25:F25) -> 2 | J25: =IF(I25>=2,H25,0) -> 18893
A26: SUMTER COUNTY JAIL | B26: Cook Inlet Pre-Trial, Anch | C26: AKCOOKI | D26: AK | G26: {=_xlfn.IFS( ISNUMBER(SEARCH("hold",C26)),"hold", ISNUMBER(SEARCH("youth",C26)),"youth", ISNUMBER(SEARCH("juve",C26)),"youth", OR(ISNUMBER(SEARCH("health",B26)),ISNUMBER(SEARCH("care ",B26)),ISNUMBER(SEARCH("psych",B26)),ISNUMBER(SEARCH("medical",B26)),ISNUMBER(SEARCH("hospital",B26))),"medical", ISNUMBER(SEARCH("correct",B26)),"correctional", ISNUMBER(SEARCH("process",B26)),"processing", ISNUMBER(SEARCH("detention center",B26)),"detention", ISNUMBER(SEARCH("detention fac",B26)),"detention", ISNUMBER(SEARCH("staging",B26)),"staging", ISNUMBER(SEARCH("prison",B26)),"prison", ISNUMBER(SEARCH("penet",B26)),"prison", ISNUMBER(SEARCH("jail",B26)),"jail", ISNUMBER(SEARCH("detention",B26)),"detention", ISNUMBER(SEARCH("sheriff",B26)),"sheriff/police", ISNUMBER(SEARCH("police",B26)),"sheriff/police", TRUE,"" )} | H26: =INDEX(Sheet2!B:B,MATCH(C26,Sheet2!A:A,0),1) -> 2 | I26: =3-COUNTBLANK(D26:F26) -> 1 | J26: =IF(I26>=2,H26,0) -> 0
A27: AZ REM OP COORD CENTER (AROCC) | B27: Joe Corley Processing Center | C27: JCRLYTX | D27: TX | E27: Conroe | G27: {=_xlfn.IFS( ISNUMBER(SEARCH("hold",C27)),"hold", ISNUMBER(SEARCH("youth",C27)),"youth", ISNUMBER(SEARCH("juve",C27)),"youth", OR(ISNUMBER(SEARCH("health",B27)),ISNUMBER(SEARCH("care ",B27)),ISNUMBER(SEARCH("psych",B27)),ISNUMBER(SEARCH("medical",B27)),ISNUMBER(SEARCH("hospital",B27))),"medical", ISNUMBER(SEARCH("correct",B27)),"correctional", ISNUMBER(SEARCH("process",B27)),"processing", ISNUMBER(SEARCH("detention center",B27)),"detention", ISNUMBER(SEARCH("detention fac",B27)),"detention", ISNUMBER(SEARCH("staging",B27)),"staging", ISNUMBER(SEARCH("prison",B27)),"prison", ISNUMBER(SEARCH("penet",B27)),"prison", ISNUMBER(SEARCH("jail",B27)),"jail", ISNUMBER(SEARCH("detention",B27)),"detention", ISNUMBER(SEARCH("sheriff",B27)),"sheriff/police", ISNUMBER(SEARCH("police",B27)),"sheriff/police", TRUE,"" )} -> processing | H27: =INDEX(Sheet2!B:B,MATCH(C27,Sheet2!A:A,0),1) -> 16030 | I27: =3-COUNTBLANK(D27:F27) -> 2 | J27: =IF(I27>=2,H27,0) -> 16030
A28: B.R.R.J. HALIFAX | B28: IAH Secure Adult Detention Facility | C28: POLKCTX | D28: TX | F28: Polk | G28: {=_xlfn.IFS( ISNUMBER(SEARCH("hold",C28)),"hold", ISNUMBER(SEARCH("youth",C28)),"youth", ISNUMBER(SEARCH("juve",C28)),"youth", OR(ISNUMBER(SEARCH("health",B28)),ISNUMBER(SEARCH("care ",B28)),ISNUMBER(SEARCH("psych",B28)),ISNUMBER(SEARCH("medical",B28)),ISNUMBER(SEARCH("hospital",B28))),"medical", ISNUMBER(SEARCH("correct",B28)),"correctional", ISNUMBER(SEARCH("process",B28)),"processing", ISNUMBER(SEARCH("detention center",B28)),"detention", ISNUMBER(SEARCH("detention fac",B28)),"detention", ISNUMBER(SEARCH("staging",B28)),"staging", ISNUMBER(SEARCH("prison",B28)),"prison", ISNUMBER(SEARCH("penet",B28)),"prison", ISNUMBER(SEARCH("jail",B28)),"jail", ISNUMBER(SEARCH("detention",B28)),"detention", ISNUMBER(SEARCH("sheriff",B28)),"sheriff/police", ISNUMBER(SEARCH("police",B28)),"sheriff/police", TRUE,"" )} -> detention | H28: =INDEX(Sheet2!B:B,MATCH(C28,Sheet2!A:A,0),1) -> 15993 | I28: =3-COUNTBLANK(D28:F28) -> 2 | J28: =IF(I28>=2,H28,0) -> 15993
A29: UNION COUNTY JAIL | B29: Ketchikan Regional Cc | C29: AKKETCH | G29: {=_xlfn.IFS( ISNUMBER(SEARCH("hold",C29)),"hold", ISNUMBER(SEARCH("youth",C29)),"youth", ISNUMBER(SEARCH("juve",C29)),"youth", OR(ISNUMBER(SEARCH("health",B29)),ISNUMBER(SEARCH("care ",B29)),ISNUMBER(SEARCH("psych",B29)),ISNUMBER(SEARCH("medical",B29)),ISNUMBER(SEARCH("hospital",B29))),"medical", ISNUMBER(SEARCH("correct",B29)),"correctional", ISNUMBER(SEARCH("process",B29)),"processing", ISNUMBER(SEARCH("detention center",B29)),"detention", ISNUMBER(SEARCH("detention fac",B29)),"detention", ISNUMBER(SEARCH("staging",B29)),"staging", ISNUMBER(SEARCH("prison",B29)),"prison", ISNUMBER(SEARCH("penet",B29)),"prison", ISNUMBER(SEARCH("jail",B29)),"jail", ISNUMBER(SEARCH("detention",B29)),"detention", ISNUMBER(SEARCH("sheriff",B29)),"sheriff/police", ISNUMBER(SEARCH("police",B29)),"sheriff/police", TRUE,"" )} | H29: =INDEX(Sheet2!B:B,MATCH(C29,Sheet2!A:A,0),1) -> 1 | I29: =3-COUNTBLANK(D29:F29) -> 0 | J29: =IF(I29>=2,H29,0) -> 0
A30: BAKER COUNTY SHERIFF DEPT. | B30: South Louisiana I.C.E. Processing Center | C30: BASILLA | D30: LA | E30: Basile | G30: {=_xlfn.IFS( ISNUMBER(SEARCH("hold",C30)),"hold", ISNUMBER(SEARCH("youth",C30)),"youth", ISNUMBER(SEARCH("juve",C30)),"youth", OR(ISNUMBER(SEARCH("health",B30)),ISNUMBER(SEARCH("care ",B30)),ISNUMBER(SEARCH("psych",B30)),ISNUMBER(SEARCH("medical",B30)),ISNUMBER(SEARCH("hospital",B30))),"medical", ISNUMBER(SEARCH("correct",B30)),"correctional", ISNUMBER(SEARCH("process",B30)),"processing", ISNUMBER(SEARCH("detention center",B30)),"detention", ISNUMBER(SEARCH("detention fac",B30)),"detention", ISNUMBER(SEARCH("staging",B30)),"staging", ISNUMBER(SEARCH("prison",B30)),"prison", ISNUMBER(SEARCH("penet",B30)),"prison", ISNUMBER(SEARCH("jail",B30)),"jail", ISNUMBER(SEARCH("detention",B30)),"detention", ISNUMBER(SEARCH("sheriff",B30)),"sheriff/police", ISNUMBER(SEARCH("police",B30)),"sheriff/police", TRUE,"" )} -> processing | H30: =INDEX(Sheet2!B:B,MATCH(C30,Sheet2!A:A,0),1) -> 15624 | I30: =3-COUNTBLANK(D30:F30) -> 2 | J30: =IF(I30>=2,H30,0) -> 15624
A31: BAKERFIELD HOLD | B31: Denver Contract Detention Facility | C31: DENICDF | D31: CO | E31: Aurora | G31: {=_xlfn.IFS( ISNUMBER(SEARCH("hold",C31)),"hold", ISNUMBER(SEARCH("youth",C31)),"youth", ISNUMBER(SEARCH("juve",C31)),"youth", OR(ISNUMBER(SEARCH("health",B31)),ISNUMBER(SEARCH("care ",B31)),ISNUMBER(SEARCH("psych",B31)),ISNUMBER(SEARCH("medical",B31)),ISNUMBER(SEARCH("hospital",B31))),"medical", ISNUMBER(SEARCH("correct",B31)),"correctional", ISNUMBER(SEARCH("process",B31)),"processing", ISNUMBER(SEARCH("detention center",B31)),"detention", ISNUMBER(SEARCH("detention fac",B31)),"detention", ISNUMBER(SEARCH("staging",B31)),"staging", ISNUMBER(SEARCH("prison",B31)),"prison", ISNUMBER(SEARCH("penet",B31)),"prison", ISNUMBER(SEARCH("jail",B31)),"jail", ISNUMBER(SEARCH("detention",B31)),"detention", ISNUMBER(SEARCH("sheriff",B31)),"sheriff/police", ISNUMBER(SEARCH("police",B31)),"sheriff/police", TRUE,"" )} -> detention | H31: =INDEX(Sheet2!B:B,MATCH(C31,Sheet2!A:A,0),1) -> 15546 | I31: =3-COUNTBLANK(D31:F31) -> 2 | J31: =IF(I31>=2,H31,0) -> 15546
A32: BALDWIN COUNTY COR. CENTER | B32: Moshannon Valley Processing Center | C32: MSVPCPA | D32: PA | E32: Philipsburg | F32: Clearfield | G32: {=_xlfn.IFS( ISNUMBER(SEARCH("hold",C32)),"hold", ISNUMBER(SEARCH("youth",C32)),"youth", ISNUMBER(SEARCH("juve",C32)),"youth", OR(ISNUMBER(SEARCH("health",B32)),ISNUMBER(SEARCH("care ",B32)),ISNUMBER(SEARCH("psych",B32)),ISNUMBER(SEARCH("medical",B32)),ISNUMBER(SEARCH("hospital",B32))),"medical", ISNUMBER(SEARCH("correct",B32)),"correctional", ISNUMBER(SEARCH("process",B32)),"processing", ISNUMBER(SEARCH("detention center",B32)),"detention", ISNUMBER(SEARCH("detention fac",B32)),"detention", ISNUMBER(SEARCH("staging",B32)),"staging", ISNUMBER(SEARCH("prison",B32)),"prison", ISNUMBER(SEARCH("penet",B32)),"prison", ISNUMBER(SEARCH("jail",B32)),"jail", ISNUMBER(SEARCH("detention",B32)),"detention", ISNUMBER(SEARCH("sheriff",B32)),"sheriff/police", ISNUMBER(SEARCH("police",B32)),"sheriff/police", TRUE,"" )} -> processing | H32: =INDEX(Sheet2!B:B,MATCH(C32,Sheet2!A:A,0),1) -> 15546 | I32: =3-COUNTBLANK(D32:F32) -> 3 | J32: =IF(I32>=2,H32,0) -> 15546
A33: BALTIMORE HOLD ROOM | B33: Houston Contract Detention Facility | C33: HOUICDF | D33: TX | E33: Houston | G33: {=_xlfn.IFS( ISNUMBER(SEARCH("hold",C33)),"hold", ISNUMBER(SEARCH("youth",C33)),"youth", ISNUMBER(SEARCH("juve",C33)),"youth", OR(ISNUMBER(SEARCH("health",B33)),ISNUMBER(SEARCH("care ",B33)),ISNUMBER(SEARCH("psych",B33)),ISNUMBER(SEARCH("medical",B33)),ISNUMBER(SEARCH("hospital",B33))),"medical", ISNUMBER(SEARCH("correct",B33)),"correctional", ISNUMBER(SEARCH("process",B33)),"processing", ISNUMBER(SEARCH("detention center",B33)),"detention", ISNUMBER(SEARCH("detention fac",B33)),"detention", ISNUMBER(SEARCH("staging",B33)),"staging", ISNUMBER(SEARCH("prison",B33)),"prison", ISNUMBER(SEARCH("penet",B33)),"prison", ISNUMBER(SEARCH("jail",B33)),"jail", ISNUMBER(SEARCH("detention",B33)),"detention", ISNUMBER(SEARCH("sheriff",B33)),"sheriff/police", ISNUMBER(SEARCH("police",B33)),"sheriff/police", TRUE,"" )} -> detention | H33: =INDEX(Sheet2!B:B,MATCH(C33,Sheet2!A:A,0),1) -> 15377 | I33: =3-COUNTBLANK(D33:F33) -> 2 | J33: =IF(I33>=2,H33,0) -> 15377
A34: SEBASTIAN COUNTY DET CNT | B34: Lemon Creek, Juneau,Ak | C34: AKLEMON | D34: AK | G34: {=_xlfn.IFS( ISNUMBER(SEARCH("hold",C34)),"hold", ISNUMBER(SEARCH("youth",C34)),"youth", ISNUMBER(SEARCH("juve",C34)),"youth", OR(ISNUMBER(SEARCH("health",B34)),ISNUMBER(SEARCH("care ",B34)),ISNUMBER(SEARCH("psych",B34)),ISNUMBER(SEARCH("medical",B34)),ISNUMBER(SEARCH("hospital",B34))),"medical", ISNUMBER(SEARCH("correct",B34)),"correctional", ISNUMBER(SEARCH("process",B34)),"processing", ISNUMBER(SEARCH("detention center",B34)),"detention", ISNUMBER(SEARCH("detention fac",B34)),"detention", ISNUMBER(SEARCH("staging",B34)),"staging", ISNUMBER(SEARCH("prison",B34)),"prison", ISNUMBER(SEARCH("penet",B34)),"prison", ISNUMBER(SEARCH("jail",B34)),"jail", ISNUMBER(SEARCH("detention",B34)),"detention", ISNUMBER(SEARCH("sheriff",B34)),"sheriff/police", ISNUMBER(SEARCH("police",B34)),"sheriff/police", TRUE,"" )} | H34: =INDEX(Sheet2!B:B,MATCH(C34,Sheet2!A:A,0),1) -> 4 | I34: =3-COUNTBLANK(D34:F34) -> 1 | J34: =IF(I34>=2,H34,0) -> 0
A35: BAPTIST MEDICAL CENTER | B35: Richwood Correctional Center | C35: RWCCMLA | D35: LA | E35: Monroe | G35: {=_xlfn.IFS( ISNUMBER(SEARCH("hold",C35)),"hold", ISNUMBER(SEARCH("youth",C35)),"youth", ISNUMBER(SEARCH("juve",C35)),"youth", OR(ISNUMBER(SEARCH("health",B35)),ISNUMBER(SEARCH("care ",B35)),ISNUMBER(SEARCH("psych",B35)),ISNUMBER(SEARCH("medical",B35)),ISNUMBER(SEARCH("hospital",B35))),"medical", ISNUMBER(SEARCH("correct",B35)),"correctional", ISNUMBER(SEARCH("process",B35)),"processing", ISNUMBER(SEARCH("detention center",B35)),"detention", ISNUMBER(SEARCH("detention fac",B35)),"detention", ISNUMBER(SEARCH("staging",B35)),"staging", ISNUMBER(SEARCH("prison",B35)),"prison", ISNUMBER(SEARCH("penet",B35)),"prison", ISNUMBER(SEARCH("jail",B35)),"jail", ISNUMBER(SEARCH("detention",B35)),"detention", ISNUMBER(SEARCH("sheriff",B35)),"sheriff/police", ISNUMBER(SEARCH("police",B35)),"sheriff/police", TRUE,"" )} -> correctional | H35: =INDEX(Sheet2!B:B,MATCH(C35,Sheet2!A:A,0),1) -> 14662 | I35: =3-COUNTBLANK(D35:F35) -> 2 | J35: =IF(I35>=2,H35,0) -> 14662
A36: BARTOW CO JAIL | B36: Phoenix District Office | C36: PHOHOLD | D36: AZ | E36: Phoenix | G36: {=_xlfn.IFS( ISNUMBER(SEARCH("hold",C36)),"hold", ISNUMBER(SEARCH("youth",C36)),"youth", ISNUMBER(SEARCH("juve",C36)),"youth", OR(ISNUMBER(SEARCH("health",B36)),ISNUMBER(SEARCH("care ",B36)),ISNUMBER(SEARCH("psych",B36)),ISNUMBER(SEARCH("medical",B36)),ISNUMBER(SEARCH("hospital",B36))),"medical", ISNUMBER(SEARCH("correct",B36)),"correctional", ISNUMBER(SEARCH("process",B36)),"processing", ISNUMBER(SEARCH("detention center",B36)),"detention", ISNUMBER(SEARCH("detention fac",B36)),"detention", ISNUMBER(SEARCH("staging",B36)),"staging", ISNUMBER(SEARCH("prison",B36)),"prison", ISNUMBER(SEARCH("penet",B36)),"prison", ISNUMBER(SEARCH("jail",B36)),"jail", ISNUMBER(SEARCH("detention",B36)),"detention", ISNUMBER(SEARCH("sheriff",B36)),"sheriff/police", ISNUMBER(SEARCH("police",B36)),"sheriff/police", TRUE,"" )} -> hold | H36: =INDEX(Sheet2!B:B,MATCH(C36,Sheet2!A:A,0),1) -> 14656 | I36: =3-COUNTBLANK(D36:F36) -> 2 | J36: =IF(I36>=2,H36,0) -> 14656
A37: BATAVIA COMMAND CENTER HOLDROOM | B37: Los Cust Case | C37: LOSHOLD | G37: {=_xlfn.IFS( ISNUMBER(SEARCH("hold",C37)),"hold", ISNUMBER(SEARCH("youth",C37)),"youth", ISNUMBER(SEARCH("juve",C37)),"youth", OR(ISNUMBER(SEARCH("health",B37)),ISNUMBER(SEARCH("care ",B37)),ISNUMBER(SEARCH("psych",B37)),ISNUMBER(SEARCH("medical",B37)),ISNUMBER(SEARCH("hospital",B37))),"medical", ISNUMBER(SEARCH("correct",B37)),"correctional", ISNUMBER(SEARCH("process",B37)),"processing", ISNUMBER(SEARCH("detention center",B37)),"detention", ISNUMBER(SEARCH("detention fac",B37)),"detention", ISNUMBER(SEARCH("staging",B37)),"staging", ISNUMBER(SEARCH("prison",B37)),"prison", ISNUMBER(SEARCH("penet",B37)),"prison", ISNUMBER(SEARCH("jail",B37)),"jail", ISNUMBER(SEARCH("detention",B37)),"detention", ISNUMBER(SEARCH("sheriff",B37)),"sheriff/police", ISNUMBER(SEARCH("police",B37)),"sheriff/police", TRUE,"" )} -> hold | H37: =INDEX(Sheet2!B:B,MATCH(C37,Sheet2!A:A,0),1) -> 13945 | I37: =3-COUNTBLANK(D37:F37) -> 0 | J37: =IF(I37>=2,H37,0) -> 0
A38: BAY COUNTY | B38: Az Rem Op Coord Center (Arocc) | C38: IWAHOLD | D38: AZ | E38: Mesa | G38: {=_xlfn.IFS( ISNUMBER(SEARCH("hold",C38)),"hold", ISNUMBER(SEARCH("youth",C38)),"youth", ISNUMBER(SEARCH("juve",C38)),"youth", OR(ISNUMBER(SEARCH("health",B38)),ISNUMBER(SEARCH("care ",B38)),ISNUMBER(SEARCH("psych",B38)),ISNUMBER(SEARCH("medical",B38)),ISNUMBER(SEARCH("hospital",B38))),"medical", ISNUMBER(SEARCH("correct",B38)),"correctional", ISNUMBER(SEARCH("process",B38)),"processing", ISNUMBER(SEARCH("detention center",B38)),"detention", ISNUMBER(SEARCH("detention fac",B38)),"detention", ISNUMBER(SEARCH("staging",B38)),"staging", ISNUMBER(SEARCH("prison",B38)),"prison", ISNUMBER(SEARCH("penet",B38)),"prison", ISNUMBER(SEARCH("jail",B38)),"jail", ISNUMBER(SEARCH("detention",B38)),"detention", ISNUMBER(SEARCH("sheriff",B38)),"sheriff/police", ISNUMBER(SEARCH("police",B38)),"sheriff/police", TRUE,"" )} -> hold | H38: =INDEX(Sheet2!B:B,MATCH(C38,Sheet2!A:A,0),1) -> 12934 | I38: =3-COUNTBLANK(D38:F38) -> 2 | J38: =IF(I38>=2,H38,0) -> 12934
A39: BAYAMON HOSPITAL | B39: Atlanta Dist. Hold Room | C39: ATLHOLD | D39: GA | E39: Atlanta | G39: {=_xlfn.IFS( ISNUMBER(SEARCH("hold",C39)),"hold", ISNUMBER(SEARCH("youth",C39)),"youth", ISNUMBER(SEARCH("juve",C39)),"youth", OR(ISNUMBER(SEARCH("health",B39)),ISNUMBER(SEARCH("care ",B39)),ISNUMBER(SEARCH("psych",B39)),ISNUMBER(SEARCH("medical",B39)),ISNUMBER(SEARCH("hospital",B39))),"medical", ISNUMBER(SEARCH("correct",B39)),"correctional", ISNUMBER(SEARCH("process",B39)),"processing", ISNUMBER(SEARCH("detention center",B39)),"detention", ISNUMBER(SEARCH("detention fac",B39)),"detention", ISNUMBER(SEARCH("staging",B39)),"staging", ISNUMBER(SEARCH("prison",B39)),"prison", ISNUMBER(SEARCH("penet",B39)),"prison", ISNUMBER(SEARCH("jail",B39)),"jail", ISNUMBER(SEARCH("detention",B39)),"detention", ISNUMBER(SEARCH("sheriff",B39)),"sheriff/police", ISNUMBER(SEARCH("police",B39)),"sheriff/police", TRUE,"" )} -> hold | H39: =INDEX(Sheet2!B:B,MATCH(C39,Sheet2!A:A,0),1) -> 12564 | I39: =3-COUNTBLANK(D39:F39) -> 2 | J39: =IF(I39>=2,H39,0) -> 12564
A40: BELL COUNTY JAIL | B40: Rio Grande Detention Center | C40: RGRNDTX | D40: TX | E40: Rio Grande | G40: {=_xlfn.IFS( ISNUMBER(SEARCH("hold",C40)),"hold", ISNUMBER(SEARCH("youth",C40)),"youth", ISNUMBER(SEARCH("juve",C40)),"youth", OR(ISNUMBER(SEARCH("health",B40)),ISNUMBER(SEARCH("care ",B40)),ISNUMBER(SEARCH("psych",B40)),ISNUMBER(SEARCH("medical",B40)),ISNUMBER(SEARCH("hospital",B40))),"medical", ISNUMBER(SEARCH("correct",B40)),"correctional", ISNUMBER(SEARCH("process",B40)),"processing", ISNUMBER(SEARCH("detention center",B40)),"detention", ISNUMBER(SEARCH("detention fac",B40)),"detention", ISNUMBER(SEARCH("staging",B40)),"staging", ISNUMBER(SEARCH("prison",B40)),"prison", ISNUMBER(SEARCH("penet",B40)),"prison", ISNUMBER(SEARCH("jail",B40)),"jail", ISNUMBER(SEARCH("detention",B40)),"detention", ISNUMBER(SEARCH("sheriff",B40)),"sheriff/police", ISNUMBER(SEARCH("police",B40)),"sheriff/police", TRUE,"" )} -> detention | H40: =INDEX(Sheet2!B:B,MATCH(C40,Sheet2!A:A,0),1) -> 12550 | I40: =3-COUNTBLANK(D40:F40) -> 2 | J40: =IF(I40>=2,H40,0) -> 12550
...

Sheet Sheet2
A1: JENATLA | B1: 84941
A2: PIC | B2: 66973
A3: FSF | B3: 65977
A4: PINEPLA | B4: 35285
A5: MTGPCTX | B5: 32270
A6: EAZ | B6: 28159
A7: CCASDCA | B7: 27619 | F7: Alamosa | G7: CO
A8: STCDFTX | B8: 27318 | F8: Albuquerque | G8: NM
A9: STWRTGA | B9: 26209 | F9: Amarillo | G9: TX
A10: LAWINCI | B10: 25935 | F10: Anchorage | G10: AK
A11: FLO | B11: 25888 | F11: Austin | G11: TX
A12: ADAMSMS | B12: 25721 | F12: Batavia | G12: NY
A13: PRLDCTX | B13: 25666 | F13: Billings | G13: MT
A14: KRO | B14: 25522 | F14: Birmingham | G14: AL
A15: EPC | B15: 22591 | F15: Boise | G15: ID
A16: KRNRCTX | B16: 21935 | F16: Bowling Green | G16: KY
A17: DALHOLD | B17: 21680 | F17: Buffalo | G17: NY
A18: OTRPCNM | B18: 21573 | F18: Cedar Rapids | G18: IA
... A32: STFRCTX | B32: 14912 | F32: Eugene | G32: OR
A33: RWCCMLA | B33: 14662 | F33: Fayetteville | G33: NC *(could also be AR | H33: but ICE usage is NC)*
A34: PHOHOLD | B34: 14656 | F34: Fort Smith | G34: AR
A35: LOSHOLD | B35: 13945 | F35: Frederick | G35: MD
A36: IWAHOLD | B36: 12934 | F36: Fresno | G36: CA
A37: ATLHOLD | B37: 12564 | F37: Glenwood Springs | G37: CO
A38: RGRNDTX | B38: 12550 | F38: Grand Island | G38: NE
A39: BSAHOLD | B39: 12393 | F39: Greer | G39: SC
A40: ELZICDF | B40: 12203 | F40: Guam | G40: GU
A41: NYCHOLD | B41: 12048 | F41: Harrisonburg | G41: VA
A42: FIPCMGA | B42: 11813 | F42: Hendersonville | G42: TN
A43: BTV | B43: 10523 | F43: Houston | G43: TX
A44: CSCNWWA | B44: 10254 | F44: Idaho Falls | G44: ID
A45: MSF | B45: 10230 | F45: Indianapolis | G45: IN
... A67: WEBDCTX | B67: 6566 | F67: Saint Albans | G67: VT
A68: INPHOLD | B68: 6441 | F68: Salisbury | G68: MD *(could be NC | H68: but ICE usage is MD)*
A69: CCAFLAZ | B69: 6356 | F69: San Antonio | G69: TX
A70: RVRCCLA | B70: 6323 | F70: Seattle | G70: WA
A71: PLYMOMA | B71: 6313 | F71: Shreveport | G71: LA
A72: NVSDCNV | B72: 6246 | F72: Sioux City | G72: IA
A73: HCPSCMS | B73: 6188 | F73: Spokane | G73: WA
A74: SPMHOLD | B74: 5868 | F74: Stuart | G74: FL
...
